Workbook
Name Company_code: [1]NJ!$L$6:$L$7

Sheet Basic Details
B1: HR Information Form
B2: Title * (Mr. / Ms. / Mrs.)
B3: Name as mentioned on Aadhar Card*
B4: First Name *
B5: Middle Name
B6: Last Name *
B7: Date of Birth* (DD-MM-YYYY) | J7: Age | L7: =IF(C7="","",DATEDIF(C7,TODAY(),"Y"))
B8: Date of Joining* (DD-MM-YYYY)
B9: Designatiom
B10: Department | T10: Male
B11: Blood Group | T11: Female
B12: Religion | T12: Others
B13: Gender
B14: PAN No (Mandatory)
B15: UAN No
B16: Aadhar Card No (Mandatory)
B17: Place of Birth
B18: Nationality
B19: Marital Status (Single/ Married)
B20: Date of Marriage *(DD-MM-YYYY)
B21: Mobile Number
B22: Personal Email ID
B24: Communication Details
B25: Permanent Address | F25: Current Address
B32: Emergency Contact Details
B33: Name
B34: Location
B35: Mobile No
B36: Email ID

Sheet Family & Education Detail
B1: Employee Family Details
B2: Particulars | F2: Father | I2: Mother | L2: Spouse | O2: 1st Child | P2: 2nd Child | R2: 2nd Child
B3: First Name
B4: Last Name
B5: Gender (1st & 2nd Child)
B6: Occupation
B7: Date of Birth (DD-MM-YYYY)
B8: Birth Place
B10: Educational Information
B11: Qualification | D11: From (DD-MM-YYY) | F11: To (DD-MM-YYY) | H11: Institute Name / University | M11: Specialisation | P11: Month & Year of Passing | S11: % or Class Obtained

Sheet Employment, Bank, nomination
B1: Employment History
B2: Organisation | C2: Designation | D2: Industry | E2: Location | F2: From (DD-MM-YY) | G2: To (DD-MM-YY) | H2: Tenure
H3: =(G3-F3)/365 -> 0
H4: =(G4-F4)/365 -> 0
H5: =(G5-F5)/365 -> 0
H6: =(G6-F6)/365 -> 0
H7: =(G7-F7)/365 -> 0
H8: =(G8-F8)/365 -> 0
H9: =(G9-F9)/365 -> 0
H10: =(G10-F10)/365 -> 0
H11: =(G11-F11)/365 -> 0
H12: =(G12-F12)/365 -> 0
B14: Total Experience | D14: =SUM(H3:H12) -> 0
B16: Bank Details
B17: Bank Name
B18: Name as on Bank Acc
B19: Bank Acc No
B20: IFSC Code
B23: Gratuity & PF Nomination Form
B24: Name of Nominee/s / Beneficiary/ies | D24: Full Address of Nominee/s / Beneficiaries | F24: Relationship with the member (Employee) | H24: Date of Birth | J24: Proportion by which gratuity & PF (total benefits) will be shared by each Nominee Beneficiary

Sheet To Be filled by HR
A1: For HRD use only
A2: Emp. ID Card | H2: Issued
A3: Visiting Card | H3: Pending
A4: Uniforms Issued | H4: N/A
A5: Email I D. (Official)
A6: Mobile (If Applicable)/Contact Number (Offical)
A7: Laptop/Charger (If issued)
A8: Insurance Cards (If Applicable)
A9: Data Card (If Applicable)
A10: Stationary
A11: Bank Acct No.
A12: Company helmet
A13: Safety Items
A14: Personal E Mail ID
A15: Personal Contact Number

Sheet Joining Checklist
A1: HR CHECKLIST
C3: Name : | D3: ='Basic Details'!C3 -> 0
C4: Designation : | D4: ='Basic Details'!C9 -> 0
C5: Date of Joining : | D5: ='Basic Details'!C8 -> 0
C6: Department : | D6: ='Basic Details'!C10 -> 0
C7: Reporting to :
C8: Reporting Site :
C9: First Aid Training given :
C10: Safety Induction given :
C11: PPE's issued :
B13: Sl No | C13: Description: | D13: Status of Documents | E13: Issued By | F13: Remark
B14: 1 | C14: CV
B15: 2 | C15: Marks Card Checked
B16: 3 | C16: Experience Certificate
B17: 4 | C17: Salary Certificate
B18: 5 | C18: ID Proof
B19: 6 | C19: PAN Card
B20: 7 | C20: interview Assesment Form
B21: 8 | C21: Employment Form
B22: 9 | C22: 2 photographs
B23: 10 | C23: ESI / PF Form
B24: 11 | C24: Grauity Form
B25: 12 | C25: ID Form
... B37: 24 | C37: ESI
C41: Prepared By | D41: Checked By | F41: Date:

Sheet Joining Letter
A5: Date: | B5: Annexure-HR REC/-14
A7: From:
A8: ='Basic Details'!C3 -> 0
A11: To:
A12: The Head HR
A13: Fujitec India Private Limited.
A16: Sub: Joining Report
A18: This has reference to the offer/ appointment order dated . I hereby inform you that, I am joining duty as ___________________________ on ________________.
A20: Thanking You,
A24: Signature of the Employee Signature of the Dept Head
A27: For Office Use:
A29: EMP No:
A30: Entry in Form 12
A31: Entry in Cluster Roll
A32: PF A/c Number
... A42: Issuing of Uniform

Sheet ID Card Form
A4: ID CARD FORM
E7: E.F.NO:
A11: NAME OF THE EMPLOYEE | B11: : | C11: ='Basic Details'!C3 -> 0
A13: DESIGNATION | B13: : | C13: ='Basic Details'!C9 -> 0
A15: BLOOD GROUP | B15: : | C15: =UPPER('Basic Details'!C11:N11)
A17: RESIDENCE ADDRESS | B17: : | C17: ='Basic Details'!B26 -> 0
A20: EMERGENCY CONTACT NO | B20: : | C20: ='Basic Details'!C35 -> 0
A22: COMPANY ADDRESS | B22: : | C22: #40/1A, Lavelle Road,
C23: Bangalore - 500001

Sheet PF Declaration New
A1: New Form : 11 - Declaration Form (To be retained by the employer for future reference) EMPLOYEES' PROVIDENT FUND ORGANISATION Employees' Provident Fund Scheme, 1952 (Paragraph 34 & 57) and Employees' Pension Scheme, 1995 (Paragraph 24) (Declaration by a person taking up Employment in any Establishment on which EPF Scheme, 1952 and for EPS, 1995 is applicable)
A2: 1 | B2: Name of Member (Aadhar Name) | E2: =UPPER('Basic Details'!C3)
A3: 2 | B3: Father's Name Spouse's Name (Please tick whichever applicable) | E3: =UPPER('Family & Education Detail'!F3)
A4: 3 | B4: Date of Birth (dd/mm/yyyy) | E4: ='Basic Details'!C7 -> 0
A5: 4 | B5: Gender (Male / Female / Transgender) | E5: ='Basic Details'!C13 -> 0
A6: 5 | B6: Marital Status ? (Single/Married/Widow/Widower/Divorcee) | E6: ='Basic Details'!C19 -> 0
A7: 6 | B7: (a) eMail ID | E7: ='Basic Details'!C22 -> 0
B8: (b) Mobile No (Aadhar Registered) | E8: ='Basic Details'!C21 -> 0
A9: 7 | B9: Whether earlier member of the Employee's Provident Fund Scheme, 1952 ? | E9: Yes / No
A10: 8 | B10: Whether earlier member of the Employee's Pension Scheme, 1995 ? | E10: Yes / No
A11: 9 | B11: Previous Employment details ? (If Yes, 7 & 8 details above) a) Universal Account Number (UAN) | E11: ='Basic Details'!C15 -> 0
B12: b) Previous PF Account Number
B13: c) Date of Exit from previous Employment ? (dd/mm/yyyy)
B14: d) Scheme Certificate No (If issued)
B15: e) Pension Payment Order (PPO) (If issued)
A16: 10 | B16: a) International Worker | E16: Yes / No
B17: b) If Yes, state country of origin (name of other country)
B18: c) Passport No.
B19: d) Validity of passport (dd/mm/yyyy) to (dd/mm/yyyy)
A20: 11 | B20: KYC Details : (attach self attested copies of following KYC's) | E20: Must Enclose Scan copy for the following documents
B21: a) Bank Account No. & IFS Code
B22: b) AADHAR Number | E22: ='Basic Details'!C16
B23: c) Permanent Account Number (PAN), If available | E23: ='Basic Details'!C14 -> 0
A25: 12 | B25: First EPF Member Enrolled Date | C25: First Employment EPF Wages | D25: Are you EPF Member before 01/09/2014 | E25: If Yes, EPF Amount Withdrawn? | F25: If Yes, EPS (Pension) Amount Withdrawn? | G25: After Sep 2014 earned EPS (Pension) Amount Withdrawn before Join current Employer?
D26: Yes / No | E26: Yes / No | F26: Yes / No | G26: Yes / No
A28: UNDERTAKING
A29: 1) Certified that the particulars are true to the best of my knowledge 2) I authorise EPFO to use my Aadhar for verification / authentication / eKYC purpose for service delivery 3) Kindly transfer the fund and service details, if applicable, from the previous PF account as declared above to the present PF account. (The transfer would be possible only if the identified KYC details approved by previous employer has been verified by present employer using his Digital Signature 4) In case of changes in above details, the same will be intimated to employer at the earliest.
A30: Date:
A31: Place: | F31: Signature of Member
A33: DECLARATION BY PRESENT EMPLOYER
A34: A. The member Mr./Ms./Mrs. ……………..…………………….. Has joined on ……………………….and has een alloted PF Number ……….…….. B. In case the person was earlier not a member of EPF Scheme, 1952 and EPS, 1995: ((Post allotment of UAN) The UAN alloted or the member is) Please Tick the Appropriate Option : The KYC details of the above member in the JAN database Have not been uploaded Have been uploaded but not approved Have been uploaded and approved with DSC C. In case the person was earlier a member of EPF Scheme, 1952 and EPS 1995; The KYC details of the above member in the UAN database have been approved with Digital Signature Certificate and transfer request has been generated on portal As the DSC of establishment are not registered with EPFO, the member has been informed to file physical claim (Form-13) for transfer of funds from his previous establishment.
A35: Date : | E35: Signature of Employer with Seal of Establishment

Sheet Form 2
A1: FORM 2 ( Revised )
A2: NOMINATION AND DECLARATION FORM
A3: FOR UNEXEMPTED / EXEMPTED ESTABLISHMENTS.
A5: Declaration and Nomination Form under the Employees' Provident Funds and Employees' Pension Scheme.
A7: ( Paragraphs 33 & 61(1) of the Employees Provident Fund Scheme, 1952 and Paragraph 18 of the Employees' Pension Scheme, 1995)
A9: 1. Name ( in Block letters) | J9: : | K9: =UPPER('Basic Details'!C3)
A11: 2. Father's / Husbands Name | J11: : | K11: =UPPER('Family & Education Detail'!F3)
A13: 3. Date of Birth | J13: : | K13: ='Basic Details'!C7 -> 0
A15: 4. Sex | J15: : | K15: ='Basic Details'!C13 -> 0
A17: 5.Marital Status | J17: : | K17: ='Basic Details'!C19 -> 0
A20: 6. Account No. | J20: :
A22: 7.Address
J23: : | K23: ='Basic Details'!B26 -> 0
A24: Permanent
K25: ='Basic Details'!F26 -> 0
A26: Temporary
A28: PART - A ( EPF)
A30: I hereby nominate the person(s) / cancel the nomination made by me previously and nominate the person(s) mentioned below
A31: to receive the amount standing to my credit in the Employees' Provident Fund, in the event of my death.
A33: Name and Address of the Nominee/Nominees | E33: Nominees' relationship with the member | I33: Date of Birth | L33: Total amount of share of Accumulations in Provident Fund to be paid to each nominee | R33: If the nominee is a minor, name & relationship & address of the guardian who may receive the amount during the minority of nominee
A34: 1 | E34: 2 | I34: 3 | L34: 4 | R34: 5
E35: ='Employment, Bank, nomination'!F25 -> 0 | I35: ='Employment, Bank, nomination'!H25 -> 0 | L35: ='Employment, Bank, nomination'!J25 -> 0 | R35: 0
A36: ='Employment, Bank, nomination'!B25&B26
A38: ='Employment, Bank, nomination'!B26&B27 | E38: ='Employment, Bank, nomination'!F26 -> 0 | I38: ='Employment, Bank, nomination'!H26 -> 0 | L38: ='Employment, Bank, nomination'!J26 -> 0
A40: 0 | E40: 0 | R40: 0
A41: 0
A44: 1. Certified that I have no family as defined in para 2 (g) of the Employees' Provident Fund Scheme, 1952 and should
A45: I acquire a family hereafter the above nomination should be deemed as cancelled.
A47: 2. Certified that my Father/ Mother is/ are dependent upon me.
A49: 3. Strike out whichever is not applicable.
B52: Note : A fresh nomination shall be made by the | M52: Signature or thumb impression of the subscriber.
B53: member on his marriage and nomination
B54: made before such marriage shall be deemed
B55: to be invalid
A56: PART- B (EPS) ( Para 18)
A57: I hereby furnish below particulars of the members of my family who would be eligible to receive widow / children pension
A58: in the event of my death.
A61: S No | B61: Name of the family Member | I61: Address | O61: Date of Birth | R61: Relation with the Nominee
A62: 1 | B62: 2 | I62: 3 | O62: 4 | R62: 5
A63: 1 | B63: 0 | I63: 0 | R63: 0
...

Sheet ESIC
A1: DATA REQUIRED TO UPDATE ESIC TIC
J3: To be printed only if Employee is eligible for ESI Benefit
B4: NAME OF EMPLOYEE | C4: =UPPER('Basic Details'!C4) | E4: =UPPER('Basic Details'!C5) | G4: =UPPER('Basic Details'!C6)
C5: First Name | E5: Middle Name | G5: Last Name
B7: NAME OF FATHER | C7: =UPPER('Family & Education Detail'!F3) | G7: =UPPER('Family & Education Detail'!F4)
C8: First Name | E8: Middle Name | G8: Last Name
B10: EMP CODE | E10: DATE OF APPOINTMENT | G10: ='Basic Details'!C8 -> 0
B13: AADHAAR NO | C13: ='Basic Details'!C16
B16: NATIONALITY | C16: ='Basic Details'!C18 -> 0 | E16: INSURANCE NO
B19: DATE OF BIRTH | C19: ='Basic Details'!C7 -> 0 | E19: MARITAL STATUS | G19: ='Basic Details'!C19 -> 0
B22: DISABILITY STATUS | E22: SEX | G22: ='Basic Details'!C13 -> 0
B25: TELEPHONE NO | C25: 0 | E25: MOBILE NO | G25: ='Basic Details'!C21 -> 0
B28: E-MAIL ID | C28: ='Basic Details'!C22 -> 0 | E28: DISPENSARY
B31: PRESENT ADDRESS | C31: ='Basic Details'!F26 -> 0
B34: PERMANENT ADDRESS | C34: ='Basic Details'!B26 -> 0
B37: FAMILY PARTICULAR
A39: SN | B39: Name | C39: Date of Birth | E39: Relation With Member | G39: Whether residing with member or not | H39: Aadhaar No
A40: 1
A42: 2
A44: 3
A46: 4
B50: NOMINEE DETAILS
A52: FULL NAME OF NOMINEE
A55: ADDRESS OF NOMINEE
A58: DATE OF BIRTH OF NOMINEE
A61: RELATION WITH MEMBER
G68: Signature of Employee

Sheet Form F
B2: Gratuity FORM ‘F’
B3: [See Sub-rule (1) of Rule 6]
B4: Nomination form
B6: To,
B7: Fujitec India Pvt Ltd
B11: 1. | C11: I,
J12: (Name in full here)
C13: Whose particulars are given in the statement below, hereby nominate the person(s) mentioned below to receive the gratuity payable after my death as also the gratuity standing to my credit in the event of my death before that amount has become payable, or having become payable has not been paid and direct that the said amount of gratuity shall be paid in proportion indicated against the name(s) of the nominee(s).
B19: 2. | C19: I hereby certify that the person(s) nominated is a /are member(s) of my family with meaning of clause(h) of Section 2 of the Payment of Gratuity Act, 1972.
B22: 3. | C22: I hereby declare that I have no family with in the meaning of clause (h) of section 2 of the said Act.
B25: 4. | C25: [a] | D25: My father/mother/parents is/are not dependent on me.
C26: [b] | D26: My husband’s father/mother/parents is/are not dependent on my husband.
B28: 5. | C28: I have excluded my husband from my family by a notice dated the ________ to the controlling authority in terms of the proviso to clause (h) of Section 2 of the said Act.
B31: 6. | C31: Nomination made herein invalidates my previous nominations.
B33: Name in full with full Address of nominees(s) | E33: Relationship with the employee | H33: Age of | J33: Proportion by which the gratuity will be shared
B35: [1] | E35: [2] | H35: [3] | J35: [4]
A36: 1. | B36: , | J36: 0
A37: 2. | B37: ,
A38: 3. | B38: ,
B39: Statement
B40: 1. Name of employee in full
B41: 2. Sex (Tick one) | G41: Male | I41: Female
B42: 3. Religion
B43: 4. Whether unmarried/married/widow/widower
B44: 5. Department / Branch / Section where employed
B45: 6. Post held with Ticket, or Serial No. if any
B46: 7. Date of appointment
B47: 8. Permanent Address
D48: Village | H48: Sub-division.
D49: Post Office | G49: District | H49: State
B52: Place:
B53: Date: | H53: Signature/Thumb impression
I54: of the subscriber.
B58: Declaration by Witnesses
B60: Nomination signed / thumb-impressed before me.
B61: Name in full and full address of…….. | H61: Signature of witnesses
B63: 1. | H63: 1.
B64: 2. | H64: 2.
B66: Place:
B67: Date:
...
